Workbook
Name Slicer_Representative: #N/A

Sheet pivot
A3: Calls Count | B3: Total Amount | C3: Total Duration | D3: Average Rating | E3: 5* Calls
A4: 1000 | B4: 96623 | C4: 89850 | D4: 3.8854 | E4: 307
A9: Calls Count | B9: Total Amount | C9: Total Duration | D9: Average Rating | E9: 5* Calls
A10: 218 | B10: 20581 | C10: 19300 | D10: 3.8706422 | E10: 74
A26: Row Labels | B26: Calls Count | C26: Calls Count2
A27: Jan | B27: 19 | C27: 19 | I27: Row Labels | J27: Calls Count
A28: Feb | B28: 10 | C28: 10 | I28: Sunday | J28: 28
A29: Mar | B29: 40 | C29: 40 | I29: Monday | J29: 24
A30: Apr | B30: 40 | C30: 40 | I30: Tuesday | J30: 44
A31: May | B31: 13 | C31: 13 | I31: Wednesday | J31: 36
A32: Jun | B32: 12 | C32: 12 | I32: Thursday | J32: 33
A33: Jul | B33: 9 | C33: 9 | I33: Friday | J33: 29
A34: Aug | B34: 13 | C34: 13 | I34: Saturday | J34: 24
A35: Sep | B35: 18 | C35: 18 | I35: Grand Total | J35: 218
A36: Oct | B36: 21 | C36: 21
A37: Nov | B37: 14 | C37: 14
A38: Dec | B38: 9 | C38: 9
A39: Grand Total | B39: 218 | C39: 218
H44: selected rep | I44: =A60 -> R02
F45: FOR GRAPH
A46: Row Labels | B46: Calls Count | C46: Total Amount | F46: rep. | G46: calls | H46: amount | I46: sel. Calls | J46: sel.amt
A47: R01 | B47: 189 | C47: 18415 | F47: {=A47:C51} -> R01 | G47: 189 | H47: 18415 | I47: =IF(F47=$I$44,G47,NA()) -> #N/A | J47: =IF(F47=$I$44,H47,NA()) -> #N/A
A48: R02 | B48: 218 | C48: 20581 | F48: R02 | G48: 218 | H48: 20581 | I48: =IF(F48=$I$44,G48,NA()) -> 218 | J48: =IF(F48=$I$44,H48,NA()) -> 20581
A49: R03 | B49: 207 | C49: 20872 | F49: R03 | G49: 207 | H49: 20872 | I49: =IF(F49=$I$44,G49,NA()) -> #N/A | J49: =IF(F49=$I$44,H49,NA()) -> #N/A
A50: R04 | B50: 186 | C50: 16651 | F50: R04 | G50: 186 | H50: 16651 | I50: =IF(F50=$I$44,G50,NA()) -> #N/A | J50: =IF(F50=$I$44,H50,NA()) -> #N/A
A51: R05 | B51: 200 | C51: 20104 | F51: R05 | G51: 200 | H51: 20104 | I51: =IF(F51=$I$44,G51,NA()) -> #N/A | J51: =IF(F51=$I$44,H51,NA()) -> #N/A
A52: Grand Total | B52: 1000 | C52: 96623
A59: Row Labels
A60: R02
A61: Grand Total
E67: Calls Count | F67: Column Labels
E68: Row Labels | F68: Female | G68: Male | H68: Grand Total
E69: Cincinnati | F69: 144 | G69: 132 | H69: 276
E70: Cleveland | F70: 326 | G70: 63 | H70: 389
E71: Columbus | F71: 129 | G71: 206 | H71: 335
E72: Grand Total | F72: 599 | G72: 401 | H72: 1000
E87: Row Labels | F87: Calls Count
E88: 1 | F88: 3
E89: 2 | F89: 19
E90: 3 | F90: 35
...

Sheet Data
B1: Call Centre Data
B3: Call number | C3: Customer ID | D3: Duration | E3: Representative | F3: Date of Call | G3: Purchase Amount | H3: Satisfaction Rating | I3: FY | J3: Day of week | K3: Duration Bucket | L3: Rating rounded | P3: Customer ID | Q3: Gedner | R3: Age | S3: City
B4: Call_7271 | C4: C0003 | D4: 116 | E4: R05 | F4: 45658 | G4: 128 | H4: 4.9 | I4: =IF(MONTH(calls[[#This Row],[Date of Call]])<=6, YEAR(calls[[#This Row],[Date of Call]]), YEAR(calls[[#This Row],[Date of Call]])+1) -> 2025 | J4: =TEXT(calls[[#This Row],[Date of Call]],"DDDD") -> Wednesday | K4: {=_xlfn.IFS(calls[[#This Row],[Duration]]<=10,"Under 10 mins", calls[[#This Row],[Duration]]<=30, "10 to 30 mins", calls[[#This Row],[Duration]]<=60, "30 to 60 mins", calls[[#This Row],[Duration]]<=120, "1 to 2 hours", TRUE, "More than 2 hours")} -> 1 to 2 hours | L4: =ROUND(calls[[#This Row],[Satisfaction Rating]],0) -> 5 | P4: C0001 | Q4: Male | R4: 41 | S4: Columbus
B5: Call_7272 | C5: C0004 | D5: 119 | E5: R05 | F5: 45658 | G5: 135 | H5: 2.9 | I5: =IF(MONTH(calls[[#This Row],[Date of Call]])<=6, YEAR(calls[[#This Row],[Date of Call]]), YEAR(calls[[#This Row],[Date of Call]])+1) -> 2025 | J5: =TEXT(calls[[#This Row],[Date of Call]],"DDDD") -> Wednesday | K5: {=_xlfn.IFS(calls[[#This Row],[Duration]]<=10,"Under 10 mins", calls[[#This Row],[Duration]]<=30, "10 to 30 mins", calls[[#This Row],[Duration]]<=60, "30 to 60 mins", calls[[#This Row],[Duration]]<=120, "1 to 2 hours", TRUE, "More than 2 hours")} -> 1 to 2 hours | L5: =ROUND(calls[[#This Row],[Satisfaction Rating]],0) -> 3 | P5: C0002 | Q5: Male | R5: 31 | S5: Cleveland
B6: Call_7273 | C6: C0005 | D6: 68 | E6: R02 | F6: 45658 | G6: 66 | H6: 4.7 | I6: =IF(MONTH(calls[[#This Row],[Date of Call]])<=6, YEAR(calls[[#This Row],[Date of Call]]), YEAR(calls[[#This Row],[Date of Call]])+1) -> 2025 | J6: =TEXT(calls[[#This Row],[Date of Call]],"DDDD") -> Wednesday | K6: {=_xlfn.IFS(calls[[#This Row],[Duration]]<=10,"Under 10 mins", calls[[#This Row],[Duration]]<=30, "10 to 30 mins", calls[[#This Row],[Duration]]<=60, "30 to 60 mins", calls[[#This Row],[Duration]]<=120, "1 to 2 hours", TRUE, "More than 2 hours")} -> 1 to 2 hours | L6: =ROUND(calls[[#This Row],[Satisfaction Rating]],0) -> 5 | P6: C0003 | Q6: Male | R6: 26 | S6: Cincinnati
B7: Call_7274 | C7: C0014 | D7: 119 | E7: R02 | F7: 45658 | G7: 22 | H7: 2.9 | I7: =IF(MONTH(calls[[#This Row],[Date of Call]])<=6, YEAR(calls[[#This Row],[Date of Call]]), YEAR(calls[[#This Row],[Date of Call]])+1) -> 2025 | J7: =TEXT(calls[[#This Row],[Date of Call]],"DDDD") -> Wednesday | K7: {=_xlfn.IFS(calls[[#This Row],[Duration]]<=10,"Under 10 mins", calls[[#This Row],[Duration]]<=30, "10 to 30 mins", calls[[#This Row],[Duration]]<=60, "30 to 60 mins", calls[[#This Row],[Duration]]<=120, "1 to 2 hours", TRUE, "More than 2 hours")} -> 1 to 2 hours | L7: =ROUND(calls[[#This Row],[Satisfaction Rating]],0) -> 3 | P7: C0004 | Q7: Male | R7: 36 | S7: Cincinnati
B8: Call_7275 | C8: C0011 | D8: 128 | E8: R01 | F8: 45659 | G8: 31 | H8: 2.8 | I8: =IF(MONTH(calls[[#This Row],[Date of Call]])<=6, YEAR(calls[[#This Row],[Date of Call]]), YEAR(calls[[#This Row],[Date of Call]])+1) -> 2025 | J8: =TEXT(calls[[#This Row],[Date of Call]],"DDDD") -> Thursday | K8: {=_xlfn.IFS(calls[[#This Row],[Duration]]<=10,"Under 10 mins", calls[[#This Row],[Duration]]<=30, "10 to 30 mins", calls[[#This Row],[Duration]]<=60, "30 to 60 mins", calls[[#This Row],[Duration]]<=120, "1 to 2 hours", TRUE, "More than 2 hours")} -> More than 2 hours | L8: =ROUND(calls[[#This Row],[Satisfaction Rating]],0) -> 3 | P8: C0005 | Q8: Male | R8: 37 | S8: Columbus
B9: Call_7276 | C9: C0011 | D9: 49 | E9: R02 | F9: 45660 | G9: 135 | H9: 4.8 | I9: =IF(MONTH(calls[[#This Row],[Date of Call]])<=6, YEAR(calls[[#This Row],[Date of Call]]), YEAR(calls[[#This Row],[Date of Call]])+1) -> 2025 | J9: =TEXT(calls[[#This Row],[Date of Call]],"DDDD") -> Friday | K9: {=_xlfn.IFS(calls[[#This Row],[Duration]]<=10,"Under 10 mins", calls[[#This Row],[Duration]]<=30, "10 to 30 mins", calls[[#This Row],[Duration]]<=60, "30 to 60 mins", calls[[#This Row],[Duration]]<=120, "1 to 2 hours", TRUE, "More than 2 hours")} -> 30 to 60 mins | L9: =ROUND(calls[[#This Row],[Satisfaction Rating]],0) -> 5 | P9: C0006 | Q9: Male | R9: 23 | S9: Columbus
B10: Call_7277 | C10: C0007 | D10: 84 | E10: R05 | F10: 45660 | G10: 60 | H10: 4.7 | I10: =IF(MONTH(calls[[#This Row],[Date of Call]])<=6, YEAR(calls[[#This Row],[Date of Call]]), YEAR(calls[[#This Row],[Date of Call]])+1) -> 2025 | J10: =TEXT(calls[[#This Row],[Date of Call]],"DDDD") -> Friday | K10: {=_xlfn.IFS(calls[[#This Row],[Duration]]<=10,"Under 10 mins", calls[[#This Row],[Duration]]<=30, "10 to 30 mins", calls[[#This Row],[Duration]]<=60, "30 to 60 mins", calls[[#This Row],[Duration]]<=120, "1 to 2 hours", TRUE, "More than 2 hours")} -> 1 to 2 hours | L10: =ROUND(calls[[#This Row],[Satisfaction Rating]],0) -> 5 | P10: C0007 | Q10: Female | R10: 22 | S10: Cleveland
B11: Call_7278 | C11: C0003 | D11: 103 | E11: R04 | F11: 45660 | G11: 148 | H11: 4.4 | I11: =IF(MONTH(calls[[#This Row],[Date of Call]])<=6, YEAR(calls[[#This Row],[Date of Call]]), YEAR(calls[[#This Row],[Date of Call]])+1) -> 2025 | J11: =TEXT(calls[[#This Row],[Date of Call]],"DDDD") -> Friday | K11: {=_xlfn.IFS(calls[[#This Row],[Duration]]<=10,"Under 10 mins", calls[[#This Row],[Duration]]<=30, "10 to 30 mins", calls[[#This Row],[Duration]]<=60, "30 to 60 mins", calls[[#This Row],[Duration]]<=120, "1 to 2 hours", TRUE, "More than 2 hours")} -> 1 to 2 hours | L11: =ROUND(calls[[#This Row],[Satisfaction Rating]],0) -> 4 | P11: C0008 | Q11: Female | R11: 42 | S11: Cleveland
B12: Call_7279 | C12: C0005 | D12: 31 | E12: R02 | F12: 45660 | G12: 135 | H12: 3.6 | I12: =IF(MONTH(calls[[#This Row],[Date of Call]])<=6, YEAR(calls[[#This Row],[Date of Call]]), YEAR(calls[[#This Row],[Date of Call]])+1) -> 2025 | J12: =TEXT(calls[[#This Row],[Date of Call]],"DDDD") -> Friday | K12: {=_xlfn.IFS(calls[[#This Row],[Duration]]<=10,"Under 10 mins", calls[[#This Row],[Duration]]<=30, "10 to 30 mins", calls[[#This Row],[Duration]]<=60, "30 to 60 mins", calls[[#This Row],[Duration]]<=120, "1 to 2 hours", TRUE, "More than 2 hours")} -> 30 to 60 mins | L12: =ROUND(calls[[#This Row],[Satisfaction Rating]],0) -> 4 | P12: C0009 | Q12: Female | R12: 25 | S12: Columbus
B13: Call_7280 | C13: C0010 | D13: 44 | E13: R03 | F13: 45660 | G13: 105 | H13: 2.9 | I13: =IF(MONTH(calls[[#This Row],[Date of Call]])<=6, YEAR(calls[[#This Row],[Date of Call]]), YEAR(calls[[#This Row],[Date of Call]])+1) -> 2025 | J13: =TEXT(calls[[#This Row],[Date of Call]],"DDDD") -> Friday | K13: {=_xlfn.IFS(calls[[#This Row],[Duration]]<=10,"Under 10 mins", calls[[#This Row],[Duration]]<=30, "10 to 30 mins", calls[[#This Row],[Duration]]<=60, "30 to 60 mins", calls[[#This Row],[Duration]]<=120, "1 to 2 hours", TRUE, "More than 2 hours")} -> 30 to 60 mins | L13: =ROUND(calls[[#This Row],[Satisfaction Rating]],0) -> 3 | P13: C0010 | Q13: Female | R13: 30 | S13: Cleveland
B14: Call_7281 | C14: C0011 | D14: 102 | E14: R02 | F14: 45660 | G14: 69 | H14: 4.9 | I14: =IF(MONTH(calls[[#This Row],[Date of Call]])<=6, YEAR(calls[[#This Row],[Date of Call]]), YEAR(calls[[#This Row],[Date of Call]])+1) -> 2025 | J14: =TEXT(calls[[#This Row],[Date of Call]],"DDDD") -> Friday | K14: {=_xlfn.IFS(calls[[#This Row],[Duration]]<=10,"Under 10 mins", calls[[#This Row],[Duration]]<=30, "10 to 30 mins", calls[[#This Row],[Duration]]<=60, "30 to 60 mins", calls[[#This Row],[Duration]]<=120, "1 to 2 hours", TRUE, "More than 2 hours")} -> 1 to 2 hours | L14: =ROUND(calls[[#This Row],[Satisfaction Rating]],0) -> 5 | P14: C0011 | Q14: Female | R14: 30 | S14: Cincinnati
B15: Call_7282 | C15: C0013 | D15: 135 | E15: R05 | F15: 45660 | G15: 46 | H15: 3.4 | I15: =IF(MONTH(calls[[#This Row],[Date of Call]])<=6, YEAR(calls[[#This Row],[Date of Call]]), YEAR(calls[[#This Row],[Date of Call]])+1) -> 2025 | J15: =TEXT(calls[[#This Row],[Date of Call]],"DDDD") -> Friday | K15: {=_xlfn.IFS(calls[[#This Row],[Duration]]<=10,"Under 10 mins", calls[[#This Row],[Duration]]<=30, "10 to 30 mins", calls[[#This Row],[Duration]]<=60, "30 to 60 mins", calls[[#This Row],[Duration]]<=120, "1 to 2 hours", TRUE, "More than 2 hours")} -> More than 2 hours | L15: =ROUND(calls[[#This Row],[Satisfaction Rating]],0) -> 3 | P15: C0012 | Q15: Female | R15: 28 | S15: Cincinnati
... B18: Call_7285 | C18: C0013 | D18: 48 | E18: R01 | F18: 45661 | G18: 68 | H18: 4.9 | I18: =IF(MONTH(calls[[#This Row],[Date of Call]])<=6, YEAR(calls[[#This Row],[Date of Call]]), YEAR(calls[[#This Row],[Date of Call]])+1) -> 2025 | J18: =TEXT(calls[[#This Row],[Date of Call]],"DDDD") -> Saturday | K18: {=_xlfn.IFS(calls[[#This Row],[Duration]]<=10,"Under 10 mins", calls[[#This Row],[Duration]]<=30, "10 to 30 mins", calls[[#This Row],[Duration]]<=60, "30 to 60 mins", calls[[#This Row],[Duration]]<=120, "1 to 2 hours", TRUE, "More than 2 hours")} -> 30 to 60 mins | L18: =ROUND(calls[[#This Row],[Satisfaction Rating]],0) -> 5 | P18: C0015 | Q18: Female | R18: 43 | S18: Cleveland
B19: Call_7286 | C19: C0010 | D19: 176 | E19: R05 | F19: 45662 | G19: 24 | H19: 4.8 | I19: =IF(MONTH(calls[[#This Row],[Date of Call]])<=6, YEAR(calls[[#This Row],[Date of Call]]), YEAR(calls[[#This Row],[Date of Call]])+1) -> 2025 | J19: =TEXT(calls[[#This Row],[Date of Call]],"DDDD") -> Sunday | K19: {=_xlfn.IFS(calls[[#This Row],[Duration]]<=10,"Under 10 mins", calls[[#This Row],[Duration]]<=30, "10 to 30 mins", calls[[#This Row],[Duration]]<=60, "30 to 60 mins", calls[[#This Row],[Duration]]<=120, "1 to 2 hours", TRUE, "More than 2 hours")} -> More than 2 hours | L19: =ROUND(calls[[#This Row],[Satisfaction Rating]],0) -> 5
B20: Call_7287 | C20: C0010 | D20: 99 | E20: R01 | F20: 45662 | G20: 195 | H20: 3.9 | I20: =IF(MONTH(calls[[#This Row],[Date of Call]])<=6, YEAR(calls[[#This Row],[Date of Call]]), YEAR(calls[[#This Row],[Date of Call]])+1) -> 2025 | J20: =TEXT(calls[[#This Row],[Date of Call]],"DDDD") -> Sunday | K20: {=_xlfn.IFS(calls[[#This Row],[Duration]]<=10,"Under 10 mins", calls[[#This Row],[Duration]]<=30, "10 to 30 mins", calls[[#This Row],[Duration]]<=60, "30 to 60 mins", calls[[#This Row],[Duration]]<=120, "1 to 2 hours", TRUE, "More than 2 hours")} -> 1 to 2 hours | L20: =ROUND(calls[[#This Row],[Satisfaction Rating]],0) -> 4
B21: Call_7288 | C21: C0009 | D21: 28 | E21: R03 | F21: 45662 | G21: 28 | H21: 3.8 | I21: =IF(MONTH(calls[[#This Row],[Date of Call]])<=6, YEAR(calls[[#This Row],[Date of Call]]), YEAR(calls[[#This Row],[Date of Call]])+1) -> 2025 | J21: =TEXT(calls[[#This Row],[Date of Call]],"DDDD") -> Sunday | K21: {=_xlfn.IFS(calls[[#This Row],[Duration]]<=10,"Under 10 mins", calls[[#This Row],[Duration]]<=30, "10 to 30 mins", calls[[#This Row],[Duration]]<=60, "30 to 60 mins", calls[[#This Row],[Duration]]<=120, "1 to 2 hours", TRUE, "More than 2 hours")} -> 10 to 30 mins | L21: =ROUND(calls[[#This Row],[Satisfaction Rating]],0) -> 4
B22: Call_7289 | C22: C0007 | D22: 54 | E22: R02 | F22: 45662 | G22: 170 | H22: 4.3 | I22: =IF(MONTH(calls[[#This Row],[Date of Call]])<=6, YEAR(calls[[#This Row],[Date of Call]]), YEAR(calls[[#This Row],[Date of Call]])+1) -> 2025 | J22: =TEXT(calls[[#This Row],[Date of Call]],"DDDD") -> Sunday | K22: {=_xlfn.IFS(calls[[#This Row],[Duration]]<=10,"Under 10 mins", calls[[#This Row],[Duration]]<=30, "10 to 30 mins", calls[[#This Row],[Duration]]<=60, "30 to 60 mins", calls[[#This Row],[Duration]]<=120, "1 to 2 hours", TRUE, "More than 2 hours")} -> 30 to 60 mins | L22: =ROUND(calls[[#This Row],[Satisfaction Rating]],0) -> 4
B23: Call_7290 | C23: C0006 | D23: 48 | E23: R05 | F23: 45663 | G23: 30 | H23: 4.4 | I23: =IF(MONTH(calls[[#This Row],[Date of Call]])<=6, YEAR(calls[[#This Row],[Date of Call]]), YEAR(calls[[#This Row],[Date of Call]])+1) -> 2025 | J23: =TEXT(calls[[#This Row],[Date of Call]],"DDDD") -> Monday | K23: {=_xlfn.IFS(calls[[#This Row],[Duration]]<=10,"Under 10 mins", calls[[#This Row],[Duration]]<=30, "10 to 30 mins", calls[[#This Row],[Duration]]<=60, "30 to 60 mins", calls[[#This Row],[Duration]]<=120, "1 to 2 hours", TRUE, "More than 2 hours")} -> 30 to 60 mins | L23: =ROUND(calls[[#This Row],[Satisfaction Rating]],0) -> 4
B24: Call_7291 | C24: C0004 | D24: 128 | E24: R05 | F24: 45663 | G24: 72 | H24: 5 | I24: =IF(MONTH(calls[[#This Row],[Date of Call]])<=6, YEAR(calls[[#This Row],[Date of Call]]), YEAR(calls[[#This Row],[Date of Call]])+1) -> 2025 | J24: =TEXT(calls[[#This Row],[Date of Call]],"DDDD") -> Monday | K24: {=_xlfn.IFS(calls[[#This Row],[Duration]]<=10,"Under 10 mins", calls[[#This Row],[Duration]]<=30, "10 to 30 mins", calls[[#This Row],[Duration]]<=60, "30 to 60 mins", calls[[#This Row],[Duration]]<=120, "1 to 2 hours", TRUE, "More than 2 hours")} -> More than 2 hours | L24: =ROUND(calls[[#This Row],[Satisfaction Rating]],0) -> 5
B25: Call_7292 | C25: C0004 | D25: 38 | E25: R04 | F25: 45664 | G25: 92 | H25: 4.9 | I25: =IF(MONTH(calls[[#This Row],[Date of Call]])<=6, YEAR(calls[[#This Row],[Date of Call]]), YEAR(calls[[#This Row],[Date of Call]])+1) -> 2025 | J25: =TEXT(calls[[#This Row],[Date of Call]],"DDDD") -> Tuesday | K25: {=_xlfn.IFS(calls[[#This Row],[Duration]]<=10,"Under 10 mins", calls[[#This Row],[Duration]]<=30, "10 to 30 mins", calls[[#This Row],[Duration]]<=60, "30 to 60 mins", calls[[#This Row],[Duration]]<=120, "1 to 2 hours", TRUE, "More than 2 hours")} -> 30 to 60 mins | L25: =ROUND(calls[[#This Row],[Satisfaction Rating]],0) -> 5
B26: Call_7293 | C26: C0003 | D26: 67 | E26: R04 | F26: 45665 | G26: 165 | H26: 4.5 | I26: =IF(MONTH(calls[[#This Row],[Date of Call]])<=6, YEAR(calls[[#This Row],[Date of Call]]), YEAR(calls[[#This Row],[Date of Call]])+1) -> 2025 | J26: =TEXT(calls[[#This Row],[Date of Call]],"DDDD") -> Wednesday | K26: {=_xlfn.IFS(calls[[#This Row],[Duration]]<=10,"Under 10 mins", calls[[#This Row],[Duration]]<=30, "10 to 30 mins", calls[[#This Row],[Duration]]<=60, "30 to 60 mins", calls[[#This Row],[Duration]]<=120, "1 to 2 hours", TRUE, "More than 2 hours")} -> 1 to 2 hours | L26: =ROUND(calls[[#This Row],[Satisfaction Rating]],0) -> 5
B27: Call_7294 | C27: C0015 | D27: 58 | E27: R02 | F27: 45665 | G27: 140 | H27: 2.1 | I27: =IF(MONTH(calls[[#This Row],[Date of Call]])<=6, YEAR(calls[[#This Row],[Date of Call]]), YEAR(calls[[#This Row],[Date of Call]])+1) -> 2025 | J27: =TEXT(calls[[#This Row],[Date of Call]],"DDDD") -> Wednesday | K27: {=_xlfn.IFS(calls[[#This Row],[Duration]]<=10,"Under 10 mins", calls[[#This Row],[Duration]]<=30, "10 to 30 mins", calls[[#This Row],[Duration]]<=60, "30 to 60 mins", calls[[#This Row],[Duration]]<=120, "1 to 2 hours", TRUE, "More than 2 hours")} -> 30 to 60 mins | L27: =ROUND(calls[[#This Row],[Satisfaction Rating]],0) -> 2
B28: Call_7295 | C28: C0010 | D28: 54 | E28: R01 | F28: 45665 | G28: 111 | H28: 3.3 | I28: =IF(MONTH(calls[[#This Row],[Date of Call]])<=6, YEAR(calls[[#This Row],[Date of Call]]), YEAR(calls[[#This Row],[Date of Call]])+1) -> 2025 | J28: =TEXT(calls[[#This Row],[Date of Call]],"DDDD") -> Wednesday | K28: {=_xlfn.IFS(calls[[#This Row],[Duration]]<=10,"Under 10 mins", calls[[#This Row],[Duration]]<=30, "10 to 30 mins", calls[[#This Row],[Duration]]<=60, "30 to 60 mins", calls[[#This Row],[Duration]]<=120, "1 to 2 hours", TRUE, "More than 2 hours")} -> 30 to 60 mins | L28: =ROUND(calls[[#This Row],[Satisfaction Rating]],0) -> 3
B29: Call_7296 | C29: C0012 | D29: 28 | E29: R05 | F29: 45666 | G29: 63 | H29: 4.1 | I29: =IF(MONTH(calls[[#This Row],[Date of Call]])<=6, YEAR(calls[[#This Row],[Date of Call]]), YEAR(calls[[#This Row],[Date of Call]])+1) -> 2025 | J29: =TEXT(calls[[#This Row],[Date of Call]],"DDDD") -> Thursday | K29: {=_xlfn.IFS(calls[[#This Row],[Duration]]<=10,"Under 10 mins", calls[[#This Row],[Duration]]<=30, "10 to 30 mins", calls[[#This Row],[Duration]]<=60, "30 to 60 mins", calls[[#This Row],[Duration]]<=120, "1 to 2 hours", TRUE, "More than 2 hours")} -> 10 to 30 mins | L29: =ROUND(calls[[#This Row],[Satisfaction Rating]],0) -> 4
B30: Call_7297 | C30: C0002 | D30: 73 | E30: R05 | F30: 45666 | G30: 80 | H30: 4.2 | I30: =IF(MONTH(calls[[#This Row],[Date of Call]])<=6, YEAR(calls[[#This Row],[Date of Call]]), YEAR(calls[[#This Row],[Date of Call]])+1) -> 2025 | J30: =TEXT(calls[[#This Row],[Date of Call]],"DDDD") -> Thursday | K30: {=_xlfn.IFS(calls[[#This Row],[Duration]]<=10,"Under 10 mins", calls[[#This Row],[Duration]]<=30, "10 to 30 mins", calls[[#This Row],[Duration]]<=60, "30 to 60 mins", calls[[#This Row],[Duration]]<=120, "1 to 2 hours", TRUE, "More than 2 hours")} -> 1 to 2 hours | L30: =ROUND(calls[[#This Row],[Satisfaction Rating]],0) -> 4
... B1003: Call_8270 | C1003: C0009 | D1003: 114 | E1003: R01 | F1003: 46022 | G1003: 40 | H1003: 3.9 | I1003: =IF(MONTH(calls[[#This Row],[Date of Call]])<=6, YEAR(calls[[#This Row],[Date of Call]]), YEAR(calls[[#This Row],[Date of Call]])+1) -> 2026 | J1003: =TEXT(calls[[#This Row],[Date of Call]],"DDDD") -> Wednesday | K1003: {=_xlfn.IFS(calls[[#This Row],[Duration]]<=10,"Under 10 mins", calls[[#This Row],[Duration]]<=30, "10 to 30 mins", calls[[#This Row],[Duration]]<=60, "30 to 60 mins", calls[[#This Row],[Duration]]<=120, "1 to 2 hours", TRUE, "More than 2 hours")} -> 1 to 2 hours | L1003: =ROUND(calls[[#This Row],[Satisfaction Rating]],0) -> 4

Sheet Assets

Sheet Customer care report
B1: CALL CENTRE REPORT 2025
V25: R1 | W25: R2 | X25: R3 | Y25: R4 | Z25: R5 | AA25: TOTAL
U26: =pivot!E102 -> Cincinnati
U27: =pivot!E103 -> C0003 | V27: =pivot!F103 -> 891 | W27: =pivot!G103 -> 1332 | X27: =pivot!H103 -> 1282 | Y27: =pivot!I103 -> 739 | Z27: =pivot!J103 -> 560 | AA27: =pivot!K103 -> 4804
U28: =pivot!E104 -> C0004 | V28: =pivot!F104 -> 1991 | W28: =pivot!G104 -> 1886 | X28: =pivot!H104 -> 1206 | Y28: =pivot!I104 -> 884 | Z28: =pivot!J104 -> 1722 | AA28: =pivot!K104 -> 7689
U29: =pivot!E105 -> C0011 | V29: =pivot!F105 -> 1163 | W29: =pivot!G105 -> 1180 | X29: =pivot!H105 -> 1616 | Y29: =pivot!I105 -> 1043 | Z29: =pivot!J105 -> 1747 | AA29: =pivot!K105 -> 6749
U30: =pivot!E106 -> C0012 | V30: =pivot!F106 -> 1438 | W30: =pivot!G106 -> 1616 | X30: =pivot!H106 -> 866 | Y30: =pivot!I106 -> 829 | Z30: =pivot!J106 -> 2070 | AA30: =pivot!K106 -> 6819
U31: =pivot!E107 -> Cleveland
U32: =pivot!E108 -> C0002 | V32: =pivot!F108 -> 1233 | W32: =pivot!G108 -> 223 | X32: =pivot!H108 -> 1680 | Y32: =pivot!I108 -> 990 | Z32: =pivot!J108 -> 1508 | AA32: =pivot!K108 -> 5634
U33: =pivot!E109 -> C0007 | V33: =pivot!F109 -> 1598 | W33: =pivot!G109 -> 1907 | X33: =pivot!H109 -> 869 | Y33: =pivot!I109 -> 1426 | Z33: =pivot!J109 -> 1416 | AA33: =pivot!K109 -> 7216
U34: =pivot!E110 -> C0008 | V34: =pivot!F110 -> 900 | W34: =pivot!G110 -> 1016 | X34: =pivot!H110 -> 960 | Y34: =pivot!I110 -> 940 | Z34: =pivot!J110 -> 1193 | AA34: =pivot!K110 -> 5009
U35: =pivot!E111 -> C0010 | V35: =pivot!F111 -> 900 | W35: =pivot!G111 -> 1470 | X35: =pivot!H111 -> 1617 | Y35: =pivot!I111 -> 1314 | Z35: =pivot!J111 -> 941 | AA35: =pivot!K111 -> 6242
U36: =pivot!E112 -> C0013 | V36: =pivot!F112 -> 1255 | W36: =pivot!G112 -> 516 | X36: =pivot!H112 -> 1874 | Y36: =pivot!I112 -> 1863 | Z36: =pivot!J112 -> 1722 | AA36: =pivot!K112 -> 7230
U37: =pivot!E113 -> C0015 | V37: =pivot!F113 -> 1138 | W37: =pivot!G113 -> 1898 | X37: =pivot!H113 -> 1482 | Y37: =pivot!I113 -> 846 | Z37: =pivot!J113 -> 1154 | AA37: =pivot!K113 -> 6518
U38: =pivot!E114 -> Columbus
U39: =pivot!E115 -> C0001 | V39: =pivot!F115 -> 1655 | W39: =pivot!G115 -> 805 | X39: =pivot!H115 -> 2263 | Y39: =pivot!I115 -> 987 | Z39: =pivot!J115 -> 1075 | AA39: =pivot!K115 -> 6785
U40: =pivot!E116 -> C0005 | V40: =pivot!F116 -> 1104 | W40: =pivot!G116 -> 2280 | X40: =pivot!H116 -> 1445 | Y40: =pivot!I116 -> 1722 | Z40: =pivot!J116 -> 1196 | AA40: =pivot!K116 -> 7747
U41: =pivot!E117 -> C0006 | V41: =pivot!F117 -> 372 | W41: =pivot!G117 -> 1818 | X41: =pivot!H117 -> 1346 | Y41: =pivot!I117 -> 1156 | Z41: =pivot!J117 -> 1484 | AA41: =pivot!K117 -> 6176
U42: =pivot!E118 -> C0009 | V42: =pivot!F118 -> 1415 | W42: =pivot!G118 -> 1271 | X42: =pivot!H118 -> 1214 | Y42: =pivot!I118 -> 1135 | Z42: =pivot!J118 -> 1566 | AA42: =pivot!K118 -> 6601
U43: =pivot!E119 -> C0014 | V43: =pivot!F119 -> 1362 | W43: =pivot!G119 -> 1363 | X43: =pivot!H119 -> 1152 | Y43: =pivot!I119 -> 777 | Z43: =pivot!J119 -> 750 | AA43: =pivot!K119 -> 5404
